<?xml version="1.0" encoding="utf-8"?>
<robot name="paul"><link name="2af714b5"><collision><geometry><box size="0.2 0.2 0.2"></box></geometry><origin xyz="0 0.0 0.0" rpy="0 0 0"></origin></collision><visual><geometry><box size="0.2 0.2 0.2"></box></geometry><origin xyz="0 0.0 0" rpy="0 0 0"></origin><material name="white"><color rgba="1 1.0 1.0 1.0"></color></material></visual><inertial><origin xyz="0 0 0" rpy="0 0 0"></origin><mass value="1"></mass><inertia ixy="0.0" ixx="0.000" ixz="0.0" iyz="0.0" iyy="0.000" izz="0.0"></inertia></inertial></link><link name="250b9131"><collision><geometry><box size="0.2 0.2 0.2"></box></geometry><origin xyz="0 0.0 0.0" rpy="0 0 0"></origin></collision><visual><geometry><box size="0.2 0.2 0.2"></box></geometry><origin xyz="0 0.0 0" rpy="0 0 0"></origin><material name="white"><color rgba="1 1.0 1.0 1.0"></color></material></visual><inertial><origin xyz="0 0 0" rpy="0 0 0"></origin><mass value="1"></mass><inertia ixy="0.0" ixx="0.000" ixz="0.0" iyz="0.0" iyy="0.000" izz="0.0"></inertia></inertial></link><link name="3cb68742"><collision><geometry><box size="0.2 0.2 0.2"></box></geometry><origin xyz="0 0.0 0.0" rpy="0 0 0"></origin></collision><visual><geometry><box size="0.2 0.2 0.2"></box></geometry><origin xyz="0 0.0 0" rpy="0 0 0"></origin><material name="white"><color rgba="1 1.0 1.0 1.0"></color></material></visual><inertial><origin xyz="0 0 0" rpy="0 0 0"></origin><mass value="1"></mass><inertia ixy="0.0" ixx="0.000" ixz="0.0" iyz="0.0" iyy="0.000" izz="0.0"></inertia></inertial></link><link name="3cb9098e"><collision><geometry><box size="0.2 0.2 0.2"></box></geometry><origin xyz="0 0.0 0.0" rpy="0 0 0"></origin></collision><visual><geometry><box size="0.2 0.2 0.2"></box></geometry><origin xyz="0 0.0 0" rpy="0 0 0"></origin><material name="white"><color rgba="1 1.0 1.0 1.0"></color></material></visual><inertial><origin xyz="0 0 0" rpy="0 0 0"></origin><mass value="1"></mass><inertia ixy="0.0" ixx="0.000" ixz="0.0" iyz="0.0" iyy="0.000" izz="0.0"></inertia></inertial></link><link name="bc2255c6"><collision><geometry><box size="0.2 0.2 0.2"></box></geometry><origin xyz="0 0.0 0.0" rpy="0 0 0"></origin></collision><visual><geometry><box size="0.2 0.2 0.2"></box></geometry><origin xyz="0 0.0 0" rpy="0 0 0"></origin><material name="white"><color rgba="1 1.0 1.0 1.0"></color></material></visual><inertial><origin xyz="0 0 0" rpy="0 0 0"></origin><mass value="1"></mass><inertia ixy="0.0" ixx="0.000" ixz="0.0" iyz="0.0" iyy="0.000" izz="0.0"></inertia></inertial></link><link name="da68b957"><collision><geometry><box size="0.2 0.2 0.2"></box></geometry><origin xyz="0 0.0 0.0" rpy="0 0 0"></origin></collision><visual><geometry><box size="0.2 0.2 0.2"></box></geometry><origin xyz="0 0.0 0" rpy="0 0 0"></origin><material name="white"><color rgba="1 1.0 1.0 1.0"></color></material></visual><inertial><origin xyz="0 0 0" rpy="0 0 0"></origin><mass value="1"></mass><inertia ixy="0.0" ixx="0.000" ixz="0.0" iyz="0.0" iyy="0.000" izz="0.0"></inertia></inertial></link><joint name="da68b957bc2255c6" type="revolute"><origin xyz="0 0.2 0" rpy="0 0 0"></origin><parent link="da68b957"></parent><child link="bc2255c6"></child><limit velocity="0" lower="-1.9" upper="1.9" effort="0"></limit><type>revolute</type><axis xyz="0 0 1"></axis></joint><joint name="bc2255c6250b9131" type="revolute"><origin xyz="0 0.2 0" rpy="0 0 0"></origin><parent link="bc2255c6"></parent><child link="250b9131"></child><limit velocity="0" lower="-1.9" upper="1.9" effort="0"></limit><type>revolute</type><axis xyz="0 0 1"></axis></joint><joint name="bc2255c63cb68742" type="revolute"><origin xyz="0 0.2 0" rpy="0 0 0"></origin><parent link="bc2255c6"></parent><child link="3cb68742"></child><limit velocity="0" lower="-1.9" upper="1.9" effort="0"></limit><type>revolute</type><axis xyz="0 0 1"></axis></joint><joint name="bc2255c63cb9098e" type="revolute"><origin xyz="0 -0.2 0" rpy="0 0 0"></origin><parent link="bc2255c6"></parent><child link="3cb9098e"></child><limit velocity="0" lower="-1.9" upper="1.9" effort="0"></limit><type>revolute</type><axis xyz="0 0 1"></axis></joint><joint name="3cb9098e2af714b5" type="revolute"><origin xyz="0 0.2 0" rpy="0 0 0"></origin><parent link="3cb9098e"></parent><child link="2af714b5"></child><limit velocity="0" lower="-1.9" upper="1.9" effort="0"></limit><type>revolute</type><axis xyz="0 0 1"></axis></joint></robot>