<?xml version="1.0" encoding="utf-8"?>
<robot name="paul"><link name="1d5aa4d5"><collision><geometry><box size="0.2 0.2 0.2"></box></geometry><origin xyz="0 0.0 0.0" rpy="0 0 0"></origin></collision><visual><geometry><box size="0.2 0.2 0.2"></box></geometry><origin xyz="0 0.0 0" rpy="0 0 0"></origin><material name="white"><color rgba="1 1.0 1.0 1.0"></color></material></visual><inertial><origin xyz="0 0 0" rpy="0 0 0"></origin><mass value="1"></mass><inertia ixy="0.0" ixx="0.000" ixz="0.0" iyz="0.0" iyy="0.000" izz="0.0"></inertia></inertial></link><link name="4fa08bce"><collision><geometry><box size="0.2 0.2 0.2"></box></geometry><origin xyz="0 0.0 0.0" rpy="0 0 0"></origin></collision><visual><geometry><box size="0.2 0.2 0.2"></box></geometry><origin xyz="0 0.0 0" rpy="0 0 0"></origin><material name="white"><color rgba="1 1.0 1.0 1.0"></color></material></visual><inertial><origin xyz="0 0 0" rpy="0 0 0"></origin><mass value="1"></mass><inertia ixy="0.0" ixx="0.000" ixz="0.0" iyz="0.0" iyy="0.000" izz="0.0"></inertia></inertial></link><link name="367ebd77"><collision><geometry><box size="0.2 0.2 0.2"></box></geometry><origin xyz="0 0.0 0.0" rpy="0 0 0"></origin></collision><visual><geometry><box size="0.2 0.2 0.2"></box></geometry><origin xyz="0 0.0 0" rpy="0 0 0"></origin><material name="white"><color rgba="1 1.0 1.0 1.0"></color></material></visual><inertial><origin xyz="0 0 0" rpy="0 0 0"></origin><mass value="1"></mass><inertia ixy="0.0" ixx="0.000" ixz="0.0" iyz="0.0" iyy="0.000" izz="0.0"></inertia></inertial></link><link name="f824428a"><collision><geometry><box size="0.2 0.2 0.2"></box></geometry><origin xyz="0 0.0 0.0" rpy="0 0 0"></origin></collision><visual><geometry><box size="0.2 0.2 0.2"></box></geometry><origin xyz="0 0.0 0" rpy="0 0 0"></origin><material name="white"><color rgba="1 1.0 1.0 1.0"></color></material></visual><inertial><origin xyz="0 0 0" rpy="0 0 0"></origin><mass value="1"></mass><inertia ixy="0.0" ixx="0.000" ixz="0.0" iyz="0.0" iyy="0.000" izz="0.0"></inertia></inertial></link><link name="fadabb44"><collision><geometry><box size="0.2 0.2 0.2"></box></geometry><origin xyz="0 0.0 0.0" rpy="0 0 0"></origin></collision><visual><geometry><box size="0.2 0.2 0.2"></box></geometry><origin xyz="0 0.0 0" rpy="0 0 0"></origin><material name="white"><color rgba="1 1.0 1.0 1.0"></color></material></visual><inertial><origin xyz="0 0 0" rpy="0 0 0"></origin><mass value="1"></mass><inertia ixy="0.0" ixx="0.000" ixz="0.0" iyz="0.0" iyy="0.000" izz="0.0"></inertia></inertial></link><link name="e143bdb5"><collision><geometry><box size="0.2 0.2 0.2"></box></geometry><origin xyz="0 0.0 0.0" rpy="0 0 0"></origin></collision><visual><geometry><box size="0.2 0.2 0.2"></box></geometry><origin xyz="0 0.0 0" rpy="0 0 0"></origin><material name="white"><color rgba="1 1.0 1.0 1.0"></color></material></visual><inertial><origin xyz="0 0 0" rpy="0 0 0"></origin><mass value="1"></mass><inertia ixy="0.0" ixx="0.000" ixz="0.0" iyz="0.0" iyy="0.000" izz="0.0"></inertia></inertial></link><link name="51242e42"><collision><geometry><box size="0.2 0.2 0.2"></box></geometry><origin xyz="0 0.0 0.0" rpy="0 0 0"></origin></collision><visual><geometry><box size="0.2 0.2 0.2"></box></geometry><origin xyz="0 0.0 0" rpy="0 0 0"></origin><material name="white"><color rgba="1 1.0 1.0 1.0"></color></material></visual><inertial><origin xyz="0 0 0" rpy="0 0 0"></origin><mass value="1"></mass><inertia ixy="0.0" ixx="0.000" ixz="0.0" iyz="0.0" iyy="0.000" izz="0.0"></inertia></inertial></link><link name="d3199206"><collision><geometry><box size="0.2 0.2 0.2"></box></geometry><origin xyz="0 0.0 0.0" rpy="0 0 0"></origin></collision><visual><geometry><box size="0.2 0.2 0.2"></box></geometry><origin xyz="0 0.0 0" rpy="0 0 0"></origin><material name="white"><color rgba="1 1.0 1.0 1.0"></color></material></visual><inertial><origin xyz="0 0 0" rpy="0 0 0"></origin><mass value="1"></mass><inertia ixy="0.0" ixx="0.000" ixz="0.0" iyz="0.0" iyy="0.000" izz="0.0"></inertia></inertial></link><joint name="d319920651242e42" type="revolute"><origin xyz="0 0.2 0" rpy="0 0 0"></origin><parent link="d3199206"></parent><child link="51242e42"></child><limit velocity="0" lower="-1.9" upper="1.9" effort="0"></limit><type>revolute</type><axis xyz="0 0 1"></axis></joint><joint name="51242e42e143bdb5" type="revolute"><origin xyz="0 0.2 0" rpy="0 0 0"></origin><parent link="51242e42"></parent><child link="e143bdb5"></child><limit velocity="0" lower="-1.9" upper="1.9" effort="0"></limit><type>revolute</type><axis xyz="0 0 1"></axis></joint><joint name="e143bdb5fadabb44" type="revolute"><origin xyz="0 0.2 0" rpy="0 0 0"></origin><parent link="e143bdb5"></parent><child link="fadabb44"></child><limit velocity="0" lower="-1.9" upper="1.9" effort="0"></limit><type>revolute</type><axis xyz="0 0 1"></axis></joint><joint name="fadabb44367ebd77" type="revolute"><origin xyz="0 0.2 0" rpy="0 0 0"></origin><parent link="fadabb44"></parent><child link="367ebd77"></child><limit velocity="0" lower="-1.9" upper="1.9" effort="0"></limit><type>revolute</type><axis xyz="0 0 1"></axis></joint><joint name="fadabb44f824428a" type="revolute"><origin xyz="-0.2 0 0" rpy="0 0 0"></origin><parent link="fadabb44"></parent><child link="f824428a"></child><limit velocity="0" lower="-1.9" upper="1.9" effort="0"></limit><type>revolute</type><axis xyz="0 0 1"></axis></joint><joint name="f824428a1d5aa4d5" type="revolute"><origin xyz="0 -0.2 0" rpy="0 0 0"></origin><parent link="f824428a"></parent><child link="1d5aa4d5"></child><limit velocity="0" lower="-1.9" upper="1.9" effort="0"></limit><type>revolute</type><axis xyz="0 0 1"></axis></joint><joint name="f824428a4fa08bce" type="revolute"><origin xyz="0 0 0.2" rpy="0 0 0"></origin><parent link="f824428a"></parent><child link="4fa08bce"></child><limit velocity="0" lower="-1.9" upper="1.9" effort="0"></limit><type>revolute</type><axis xyz="0 0 1"></axis></joint></robot>