<?xml version="1.0" encoding="utf-8"?>
<robot name="paul"><link name="6023bef8"><collision><geometry><box size="0.2 0.2 0.2"></box></geometry><origin xyz="0 0.0 0.0" rpy="0 0 0"></origin></collision><visual><geometry><box size="0.2 0.2 0.2"></box></geometry><origin xyz="0 0.0 0" rpy="0 0 0"></origin><material name="white"><color rgba="1 1.0 1.0 1.0"></color></material></visual><inertial><origin xyz="0 0 0" rpy="0 0 0"></origin><mass value="1"></mass><inertia ixy="0.0" ixx="0.000" ixz="0.0" iyz="0.0" iyy="0.000" izz="0.0"></inertia></inertial></link><link name="3837421a"><collision><geometry><box size="0.2 0.2 0.2"></box></geometry><origin xyz="0 0.0 0.0" rpy="0 0 0"></origin></collision><visual><geometry><box size="0.2 0.2 0.2"></box></geometry><origin xyz="0 0.0 0" rpy="0 0 0"></origin><material name="white"><color rgba="1 1.0 1.0 1.0"></color></material></visual><inertial><origin xyz="0 0 0" rpy="0 0 0"></origin><mass value="1"></mass><inertia ixy="0.0" ixx="0.000" ixz="0.0" iyz="0.0" iyy="0.000" izz="0.0"></inertia></inertial></link><link name="cf1ff730"><collision><geometry><box size="0.2 0.2 0.2"></box></geometry><origin xyz="0 0.0 0.0" rpy="0 0 0"></origin></collision><visual><geometry><box size="0.2 0.2 0.2"></box></geometry><origin xyz="0 0.0 0" rpy="0 0 0"></origin><material name="white"><color rgba="1 1.0 1.0 1.0"></color></material></visual><inertial><origin xyz="0 0 0" rpy="0 0 0"></origin><mass value="1"></mass><inertia ixy="0.0" ixx="0.000" ixz="0.0" iyz="0.0" iyy="0.000" izz="0.0"></inertia></inertial></link><link name="ce10f7fe"><collision><geometry><box size="0.2 0.2 0.2"></box></geometry><origin xyz="0 0.0 0.0" rpy="0 0 0"></origin></collision><visual><geometry><box size="0.2 0.2 0.2"></box></geometry><origin xyz="0 0.0 0" rpy="0 0 0"></origin><material name="white"><color rgba="1 1.0 1.0 1.0"></color></material></visual><inertial><origin xyz="0 0 0" rpy="0 0 0"></origin><mass value="1"></mass><inertia ixy="0.0" ixx="0.000" ixz="0.0" iyz="0.0" iyy="0.000" izz="0.0"></inertia></inertial></link><link name="60c70f33"><collision><geometry><box size="0.2 0.2 0.2"></box></geometry><origin xyz="0 0.0 0.0" rpy="0 0 0"></origin></collision><visual><geometry><box size="0.2 0.2 0.2"></box></geometry><origin xyz="0 0.0 0" rpy="0 0 0"></origin><material name="white"><color rgba="1 1.0 1.0 1.0"></color></material></visual><inertial><origin xyz="0 0 0" rpy="0 0 0"></origin><mass value="1"></mass><inertia ixy="0.0" ixx="0.000" ixz="0.0" iyz="0.0" iyy="0.000" izz="0.0"></inertia></inertial></link><link name="171d9b21"><collision><geometry><box size="0.2 0.2 0.2"></box></geometry><origin xyz="0 0.0 0.0" rpy="0 0 0"></origin></collision><visual><geometry><box size="0.2 0.2 0.2"></box></geometry><origin xyz="0 0.0 0" rpy="0 0 0"></origin><material name="white"><color rgba="1 1.0 1.0 1.0"></color></material></visual><inertial><origin xyz="0 0 0" rpy="0 0 0"></origin><mass value="1"></mass><inertia ixy="0.0" ixx="0.000" ixz="0.0" iyz="0.0" iyy="0.000" izz="0.0"></inertia></inertial></link><link name="09821ecb"><collision><geometry><box size="0.2 0.2 0.2"></box></geometry><origin xyz="0 0.0 0.0" rpy="0 0 0"></origin></collision><visual><geometry><box size="0.2 0.2 0.2"></box></geometry><origin xyz="0 0.0 0" rpy="0 0 0"></origin><material name="white"><color rgba="1 1.0 1.0 1.0"></color></material></visual><inertial><origin xyz="0 0 0" rpy="0 0 0"></origin><mass value="1"></mass><inertia ixy="0.0" ixx="0.000" ixz="0.0" iyz="0.0" iyy="0.000" izz="0.0"></inertia></inertial></link><link name="8f60c46e"><collision><geometry><box size="0.2 0.2 0.2"></box></geometry><origin xyz="0 0.0 0.0" rpy="0 0 0"></origin></collision><visual><geometry><box size="0.2 0.2 0.2"></box></geometry><origin xyz="0 0.0 0" rpy="0 0 0"></origin><material name="white"><color rgba="1 1.0 1.0 1.0"></color></material></visual><inertial><origin xyz="0 0 0" rpy="0 0 0"></origin><mass value="1"></mass><inertia ixy="0.0" ixx="0.000" ixz="0.0" iyz="0.0" iyy="0.000" izz="0.0"></inertia></inertial></link><joint name="8f60c46e09821ecb" type="revolute"><origin xyz="0 0.2 0" rpy="0 0 0"></origin><parent link="8f60c46e"></parent><child link="09821ecb"></child><limit velocity="0" lower="-1.9" upper="1.9" effort="0"></limit><type>revolute</type><axis xyz="0 0 1"></axis></joint><joint name="09821ecb171d9b21" type="revolute"><origin xyz="0 0.2 0" rpy="0 0 0"></origin><parent link="09821ecb"></parent><child link="171d9b21"></child><limit velocity="0" lower="-1.9" upper="1.9" effort="0"></limit><type>revolute</type><axis xyz="0 0 1"></axis></joint><joint name="171d9b2160c70f33" type="revolute"><origin xyz="0 0.2 0" rpy="0 0 0"></origin><parent link="171d9b21"></parent><child link="60c70f33"></child><limit velocity="0" lower="-1.9" upper="1.9" effort="0"></limit><type>revolute</type><axis xyz="0 0 1"></axis></joint><joint name="60c70f33cf1ff730" type="revolute"><origin xyz="0 0.2 0" rpy="0 0 0"></origin><parent link="60c70f33"></parent><child link="cf1ff730"></child><limit velocity="0" lower="-1.9" upper="1.9" effort="0"></limit><type>revolute</type><axis xyz="0 0 1"></axis></joint><joint name="60c70f33ce10f7fe" type="revolute"><origin xyz="-0.2 0 0" rpy="0 0 0"></origin><parent link="60c70f33"></parent><child link="ce10f7fe"></child><limit velocity="0" lower="-1.9" upper="1.9" effort="0"></limit><type>revolute</type><axis xyz="0 0 1"></axis></joint><joint name="ce10f7fe6023bef8" type="revolute"><origin xyz="0 -0.2 0" rpy="0 0 0"></origin><parent link="ce10f7fe"></parent><child link="6023bef8"></child><limit velocity="0" lower="-1.9" upper="1.9" effort="0"></limit><type>revolute</type><axis xyz="0 0 1"></axis></joint><joint name="ce10f7fe3837421a" type="revolute"><origin xyz="0 0 0.2" rpy="0 0 0"></origin><parent link="ce10f7fe"></parent><child link="3837421a"></child><limit velocity="0" lower="-1.9" upper="1.9" effort="0"></limit><type>revolute</type><axis xyz="0 0 1"></axis></joint></robot>