<?xml version="1.0" encoding="utf-8"?>
<robot name="paul"><link name="30be046c"><collision><geometry><box size="0.2 0.2 0.2"></box></geometry><origin xyz="0 0.0 0.0" rpy="0 0 0"></origin></collision><visual><geometry><box size="0.2 0.2 0.2"></box></geometry><origin xyz="0 0.0 0" rpy="0 0 0"></origin><material name="white"><color rgba="1 1.0 1.0 1.0"></color></material></visual><inertial><origin xyz="0 0 0" rpy="0 0 0"></origin><mass value="1"></mass><inertia ixy="0.0" ixx="0.000" ixz="0.0" iyz="0.0" iyy="0.000" izz="0.0"></inertia></inertial></link><link name="1ba917cd"><collision><geometry><box size="0.2 0.2 0.2"></box></geometry><origin xyz="0 0.0 0.0" rpy="0 0 0"></origin></collision><visual><geometry><box size="0.2 0.2 0.2"></box></geometry><origin xyz="0 0.0 0" rpy="0 0 0"></origin><material name="white"><color rgba="1 1.0 1.0 1.0"></color></material></visual><inertial><origin xyz="0 0 0" rpy="0 0 0"></origin><mass value="1"></mass><inertia ixy="0.0" ixx="0.000" ixz="0.0" iyz="0.0" iyy="0.000" izz="0.0"></inertia></inertial></link><link name="5cc1c2c2"><collision><geometry><box size="0.2 0.2 0.2"></box></geometry><origin xyz="0 0.0 0.0" rpy="0 0 0"></origin></collision><visual><geometry><box size="0.2 0.2 0.2"></box></geometry><origin xyz="0 0.0 0" rpy="0 0 0"></origin><material name="white"><color rgba="1 1.0 1.0 1.0"></color></material></visual><inertial><origin xyz="0 0 0" rpy="0 0 0"></origin><mass value="1"></mass><inertia ixy="0.0" ixx="0.000" ixz="0.0" iyz="0.0" iyy="0.000" izz="0.0"></inertia></inertial></link><link name="6485ace6"><collision><geometry><box size="0.2 0.2 0.2"></box></geometry><origin xyz="0 0.0 0.0" rpy="0 0 0"></origin></collision><visual><geometry><box size="0.2 0.2 0.2"></box></geometry><origin xyz="0 0.0 0" rpy="0 0 0"></origin><material name="white"><color rgba="1 1.0 1.0 1.0"></color></material></visual><inertial><origin xyz="0 0 0" rpy="0 0 0"></origin><mass value="1"></mass><inertia ixy="0.0" ixx="0.000" ixz="0.0" iyz="0.0" iyy="0.000" izz="0.0"></inertia></inertial></link><link name="19a95b51"><collision><geometry><box size="0.2 0.2 0.2"></box></geometry><origin xyz="0 0.0 0.0" rpy="0 0 0"></origin></collision><visual><geometry><box size="0.2 0.2 0.2"></box></geometry><origin xyz="0 0.0 0" rpy="0 0 0"></origin><material name="white"><color rgba="1 1.0 1.0 1.0"></color></material></visual><inertial><origin xyz="0 0 0" rpy="0 0 0"></origin><mass value="1"></mass><inertia ixy="0.0" ixx="0.000" ixz="0.0" iyz="0.0" iyy="0.000" izz="0.0"></inertia></inertial></link><link name="f13a5d97"><collision><geometry><box size="0.2 0.2 0.2"></box></geometry><origin xyz="0 0.0 0.0" rpy="0 0 0"></origin></collision><visual><geometry><box size="0.2 0.2 0.2"></box></geometry><origin xyz="0 0.0 0" rpy="0 0 0"></origin><material name="white"><color rgba="1 1.0 1.0 1.0"></color></material></visual><inertial><origin xyz="0 0 0" rpy="0 0 0"></origin><mass value="1"></mass><inertia ixy="0.0" ixx="0.000" ixz="0.0" iyz="0.0" iyy="0.000" izz="0.0"></inertia></inertial></link><link name="ba02d405"><collision><geometry><box size="0.2 0.2 0.2"></box></geometry><origin xyz="0 0.0 0.0" rpy="0 0 0"></origin></collision><visual><geometry><box size="0.2 0.2 0.2"></box></geometry><origin xyz="0 0.0 0" rpy="0 0 0"></origin><material name="white"><color rgba="1 1.0 1.0 1.0"></color></material></visual><inertial><origin xyz="0 0 0" rpy="0 0 0"></origin><mass value="1"></mass><inertia ixy="0.0" ixx="0.000" ixz="0.0" iyz="0.0" iyy="0.000" izz="0.0"></inertia></inertial></link><link name="d7a25923"><collision><geometry><box size="0.2 0.2 0.2"></box></geometry><origin xyz="0 0.0 0.0" rpy="0 0 0"></origin></collision><visual><geometry><box size="0.2 0.2 0.2"></box></geometry><origin xyz="0 0.0 0" rpy="0 0 0"></origin><material name="white"><color rgba="1 1.0 1.0 1.0"></color></material></visual><inertial><origin xyz="0 0 0" rpy="0 0 0"></origin><mass value="1"></mass><inertia ixy="0.0" ixx="0.000" ixz="0.0" iyz="0.0" iyy="0.000" izz="0.0"></inertia></inertial></link><link name="a012ceca"><collision><geometry><box size="0.2 0.2 0.2"></box></geometry><origin xyz="0 0.0 0.0" rpy="0 0 0"></origin></collision><visual><geometry><box size="0.2 0.2 0.2"></box></geometry><origin xyz="0 0.0 0" rpy="0 0 0"></origin><material name="white"><color rgba="1 1.0 1.0 1.0"></color></material></visual><inertial><origin xyz="0 0 0" rpy="0 0 0"></origin><mass value="1"></mass><inertia ixy="0.0" ixx="0.000" ixz="0.0" iyz="0.0" iyy="0.000" izz="0.0"></inertia></inertial></link><link name="a7e97cdd"><collision><geometry><box size="0.2 0.2 0.2"></box></geometry><origin xyz="0 0.0 0.0" rpy="0 0 0"></origin></collision><visual><geometry><box size="0.2 0.2 0.2"></box></geometry><origin xyz="0 0.0 0" rpy="0 0 0"></origin><material name="white"><color rgba="1 1.0 1.0 1.0"></color></material></visual><inertial><origin xyz="0 0 0" rpy="0 0 0"></origin><mass value="1"></mass><inertia ixy="0.0" ixx="0.000" ixz="0.0" iyz="0.0" iyy="0.000" izz="0.0"></inertia></inertial></link><link name="2427c4e1"><collision><geometry><box size="0.2 0.2 0.2"></box></geometry><origin xyz="0 0.0 0.0" rpy="0 0 0"></origin></collision><visual><geometry><box size="0.2 0.2 0.2"></box></geometry><origin xyz="0 0.0 0" rpy="0 0 0"></origin><material name="white"><color rgba="1 1.0 1.0 1.0"></color></material></visual><inertial><origin xyz="0 0 0" rpy="0 0 0"></origin><mass value="1"></mass><inertia ixy="0.0" ixx="0.000" ixz="0.0" iyz="0.0" iyy="0.000" izz="0.0"></inertia></inertial></link><link name="58d579ee"><collision><geometry><box size="0.2 0.2 0.2"></box></geometry><origin xyz="0 0.0 0.0" rpy="0 0 0"></origin></collision><visual><geometry><box size="0.2 0.2 0.2"></box></geometry><origin xyz="0 0.0 0" rpy="0 0 0"></origin><material name="white"><color rgba="1 1.0 1.0 1.0"></color></material></visual><inertial><origin xyz="0 0 0" rpy="0 0 0"></origin><mass value="1"></mass><inertia ixy="0.0" ixx="0.000" ixz="0.0" iyz="0.0" iyy="0.000" izz="0.0"></inertia></inertial></link><link name="9a8e9899"><collision><geometry><box size="0.2 0.2 0.2"></box></geometry><origin xyz="0 0.0 0.0" rpy="0 0 0"></origin></collision><visual><geometry><box size="0.2 0.2 0.2"></box></geometry><origin xyz="0 0.0 0" rpy="0 0 0"></origin><material name="white"><color rgba="1 1.0 1.0 1.0"></color></material></visual><inertial><origin xyz="0 0 0" rpy="0 0 0"></origin><mass value="1"></mass><inertia ixy="0.0" ixx="0.000" ixz="0.0" iyz="0.0" iyy="0.000" izz="0.0"></inertia></inertial></link><link name="83c1f939"><collision><geometry><box size="0.2 0.2 0.2"></box></geometry><origin xyz="0 0.0 0.0" rpy="0 0 0"></origin></collision><visual><geometry><box size="0.2 0.2 0.2"></box></geometry><origin xyz="0 0.0 0" rpy="0 0 0"></origin><material name="white"><color rgba="1 1.0 1.0 1.0"></color></material></visual><inertial><origin xyz="0 0 0" rpy="0 0 0"></origin><mass value="1"></mass><inertia ixy="0.0" ixx="0.000" ixz="0.0" iyz="0.0" iyy="0.000" izz="0.0"></inertia></inertial></link><link name="1f5d8327"><collision><geometry><box size="0.2 0.2 0.2"></box></geometry><origin xyz="0 0.0 0.0" rpy="0 0 0"></origin></collision><visual><geometry><box size="0.2 0.2 0.2"></box></geometry><origin xyz="0 0.0 0" rpy="0 0 0"></origin><material name="white"><color rgba="1 1.0 1.0 1.0"></color></material></visual><inertial><origin xyz="0 0 0" rpy="0 0 0"></origin><mass value="1"></mass><inertia ixy="0.0" ixx="0.000" ixz="0.0" iyz="0.0" iyy="0.000" izz="0.0"></inertia></inertial></link><link name="af362fe3"><collision><geometry><box size="0.2 0.2 0.2"></box></geometry><origin xyz="0 0.0 0.0" rpy="0 0 0"></origin></collision><visual><geometry><box size="0.2 0.2 0.2"></box></geometry><origin xyz="0 0.0 0" rpy="0 0 0"></origin><material name="white"><color rgba="1 1.0 1.0 1.0"></color></material></visual><inertial><origin xyz="0 0 0" rpy="0 0 0"></origin><mass value="1"></mass><inertia ixy="0.0" ixx="0.000" ixz="0.0" iyz="0.0" iyy="0.000" izz="0.0"></inertia></inertial></link><link name="5cdf790f"><collision><geometry><box size="0.2 0.2 0.2"></box></geometry><origin xyz="0 0.0 0.0" rpy="0 0 0"></origin></collision><visual><geometry><box size="0.2 0.2 0.2"></box></geometry><origin xyz="0 0.0 0" rpy="0 0 0"></origin><material name="white"><color rgba="1 1.0 1.0 1.0"></color></material></visual><inertial><origin xyz="0 0 0" rpy="0 0 0"></origin><mass value="1"></mass><inertia ixy="0.0" ixx="0.000" ixz="0.0" iyz="0.0" iyy="0.000" izz="0.0"></inertia></inertial></link><link name="bc62b5e3"><collision><geometry><box size="0.2 0.2 0.2"></box></geometry><origin xyz="0 0.0 0.0" rpy="0 0 0"></origin></collision><visual><geometry><box size="0.2 0.2 0.2"></box></geometry><origin xyz="0 0.0 0" rpy="0 0 0"></origin><material name="white"><color rgba="1 1.0 1.0 1.0"></color></material></visual><inertial><origin xyz="0 0 0" rpy="0 0 0"></origin><mass value="1"></mass><inertia ixy="0.0" ixx="0.000" ixz="0.0" iyz="0.0" iyy="0.000" izz="0.0"></inertia></inertial></link><link name="8bf8317a"><collision><geometry><box size="0.2 0.2 0.2"></box></geometry><origin xyz="0 0.0 0.0" rpy="0 0 0"></origin></collision><visual><geometry><box size="0.2 0.2 0.2"></box></geometry><origin xyz="0 0.0 0" rpy="0 0 0"></origin><material name="white"><color rgba="1 1.0 1.0 1.0"></color></material></visual><inertial><origin xyz="0 0 0" rpy="0 0 0"></origin><mass value="1"></mass><inertia ixy="0.0" ixx="0.000" ixz="0.0" iyz="0.0" iyy="0.000" izz="0.0"></inertia></inertial></link><joint name="8bf8317abc62b5e3" type="revolute"><origin xyz="0 0.2 0" rpy="0 0 0"></origin><parent link="8bf8317a"></parent><child link="bc62b5e3"></child><limit velocity="0" lower="-1.9" upper="1.9" effort="0"></limit><type>revolute</type><axis xyz="0 0 1"></axis></joint><joint name="bc62b5e35cdf790f" type="revolute"><origin xyz="0 0.2 0" rpy="0 0 0"></origin><parent link="bc62b5e3"></parent><child link="5cdf790f"></child><limit velocity="0" lower="-1.9" upper="1.9" effort="0"></limit><type>revolute</type><axis xyz="0 0 1"></axis></joint><joint name="5cdf790f83c1f939" type="revolute"><origin xyz="0 0.2 0" rpy="0 0 0"></origin><parent link="5cdf790f"></parent><child link="83c1f939"></child><limit velocity="0" lower="-1.9" upper="1.9" effort="0"></limit><type>revolute</type><axis xyz="0 0 1"></axis></joint><joint name="5cdf790f1f5d8327" type="revolute"><origin xyz="0 -0.2 0" rpy="0 0 0"></origin><parent link="5cdf790f"></parent><child link="1f5d8327"></child><limit velocity="0" lower="-1.9" upper="1.9" effort="0"></limit><type>revolute</type><axis xyz="0 0 1"></axis></joint><joint name="5cdf790faf362fe3" type="revolute"><origin xyz="-0.2 0 0" rpy="0 0 0"></origin><parent link="5cdf790f"></parent><child link="af362fe3"></child><limit velocity="0" lower="-1.9" upper="1.9" effort="0"></limit><type>revolute</type><axis xyz="0 0 1"></axis></joint><joint name="af362fe32427c4e1" type="revolute"><origin xyz="0 0.2 0" rpy="0 0 0"></origin><parent link="af362fe3"></parent><child link="2427c4e1"></child><limit velocity="0" lower="-1.9" upper="1.9" effort="0"></limit><type>revolute</type><axis xyz="0 0 1"></axis></joint><joint name="af362fe358d579ee" type="revolute"><origin xyz="0.2 0 0" rpy="0 0 0"></origin><parent link="af362fe3"></parent><child link="58d579ee"></child><limit velocity="0" lower="-1.9" upper="1.9" effort="0"></limit><type>revolute</type><axis xyz="0 0 1"></axis></joint><joint name="af362fe39a8e9899" type="revolute"><origin xyz="0 -0.2 0" rpy="0 0 0"></origin><parent link="af362fe3"></parent><child link="9a8e9899"></child><limit velocity="0" lower="-1.9" upper="1.9" effort="0"></limit><type>revolute</type><axis xyz="0 0 1"></axis></joint><joint name="9a8e9899a7e97cdd" type="revolute"><origin xyz="0 0.2 0" rpy="0 0 0"></origin><parent link="9a8e9899"></parent><child link="a7e97cdd"></child><limit velocity="0" lower="-1.9" upper="1.9" effort="0"></limit><type>revolute</type><axis xyz="0 0 1"></axis></joint><joint name="a7e97cdda012ceca" type="revolute"><origin xyz="0.2 0 0" rpy="0 0 0"></origin><parent link="a7e97cdd"></parent><child link="a012ceca"></child><limit velocity="0" lower="-1.9" upper="1.9" effort="0"></limit><type>revolute</type><axis xyz="0 0 1"></axis></joint><joint name="a012cecad7a25923" type="revolute"><origin xyz="0 0.2 0" rpy="0 0 0"></origin><parent link="a012ceca"></parent><child link="d7a25923"></child><limit velocity="0" lower="-1.9" upper="1.9" effort="0"></limit><type>revolute</type><axis xyz="0 0 1"></axis></joint><joint name="d7a25923ba02d405" type="revolute"><origin xyz="0 0.2 0" rpy="0 0 0"></origin><parent link="d7a25923"></parent><child link="ba02d405"></child><limit velocity="0" lower="-1.9" upper="1.9" effort="0"></limit><type>revolute</type><axis xyz="0 0 1"></axis></joint><joint name="ba02d405f13a5d97" type="revolute"><origin xyz="0 0.2 0" rpy="0 0 0"></origin><parent link="ba02d405"></parent><child link="f13a5d97"></child><limit velocity="0" lower="-1.9" upper="1.9" effort="0"></limit><type>revolute</type><axis xyz="0 0 1"></axis></joint><joint name="f13a5d976485ace6" type="revolute"><origin xyz="0 0.2 0" rpy="0 0 0"></origin><parent link="f13a5d97"></parent><child link="6485ace6"></child><limit velocity="0" lower="-1.9" upper="1.9" effort="0"></limit><type>revolute</type><axis xyz="0 0 1"></axis></joint><joint name="f13a5d9719a95b51" type="revolute"><origin xyz="0.2 0 0" rpy="0 0 0"></origin><parent link="f13a5d97"></parent><child link="19a95b51"></child><limit velocity="0" lower="-1.9" upper="1.9" effort="0"></limit><type>revolute</type><axis xyz="0 0 1"></axis></joint><joint name="19a95b515cc1c2c2" type="revolute"><origin xyz="0 0.2 0" rpy="0 0 0"></origin><parent link="19a95b51"></parent><child link="5cc1c2c2"></child><limit velocity="0" lower="-1.9" upper="1.9" effort="0"></limit><type>revolute</type><axis xyz="0 0 1"></axis></joint><joint name="5cc1c2c21ba917cd" type="revolute"><origin xyz="0 0.2 0" rpy="0 0 0"></origin><parent link="5cc1c2c2"></parent><child link="1ba917cd"></child><limit velocity="0" lower="-1.9" upper="1.9" effort="0"></limit><type>revolute</type><axis xyz="0 0 1"></axis></joint><joint name="1ba917cd30be046c" type="revolute"><origin xyz="0 0.2 0" rpy="0 0 0"></origin><parent link="1ba917cd"></parent><child link="30be046c"></child><limit velocity="0" lower="-1.9" upper="1.9" effort="0"></limit><type>revolute</type><axis xyz="0 0 1"></axis></joint></robot>