<?xml version="1.0" encoding="utf-8"?>
<robot name="paul"><link name="0fd258d7"><collision><geometry><box size="0.2 0.2 0.2"></box></geometry><origin xyz="0 0.0 0.0" rpy="0 0 0"></origin></collision><visual><geometry><box size="0.2 0.2 0.2"></box></geometry><origin xyz="0 0.0 0" rpy="0 0 0"></origin><material name="white"><color rgba="1 1.0 1.0 1.0"></color></material></visual><inertial><origin xyz="0 0 0" rpy="0 0 0"></origin><mass value="1"></mass><inertia ixy="0.0" ixx="0.000" ixz="0.0" iyz="0.0" iyy="0.000" izz="0.0"></inertia></inertial></link><link name="b066414d"><collision><geometry><box size="0.2 0.2 0.2"></box></geometry><origin xyz="0 0.0 0.0" rpy="0 0 0"></origin></collision><visual><geometry><box size="0.2 0.2 0.2"></box></geometry><origin xyz="0 0.0 0" rpy="0 0 0"></origin><material name="white"><color rgba="1 1.0 1.0 1.0"></color></material></visual><inertial><origin xyz="0 0 0" rpy="0 0 0"></origin><mass value="1"></mass><inertia ixy="0.0" ixx="0.000" ixz="0.0" iyz="0.0" iyy="0.000" izz="0.0"></inertia></inertial></link><link name="38092bac"><collision><geometry><box size="0.2 0.2 0.2"></box></geometry><origin xyz="0 0.0 0.0" rpy="0 0 0"></origin></collision><visual><geometry><box size="0.2 0.2 0.2"></box></geometry><origin xyz="0 0.0 0" rpy="0 0 0"></origin><material name="white"><color rgba="1 1.0 1.0 1.0"></color></material></visual><inertial><origin xyz="0 0 0" rpy="0 0 0"></origin><mass value="1"></mass><inertia ixy="0.0" ixx="0.000" ixz="0.0" iyz="0.0" iyy="0.000" izz="0.0"></inertia></inertial></link><link name="62d6a4e2"><collision><geometry><box size="0.2 0.2 0.2"></box></geometry><origin xyz="0 0.0 0.0" rpy="0 0 0"></origin></collision><visual><geometry><box size="0.2 0.2 0.2"></box></geometry><origin xyz="0 0.0 0" rpy="0 0 0"></origin><material name="white"><color rgba="1 1.0 1.0 1.0"></color></material></visual><inertial><origin xyz="0 0 0" rpy="0 0 0"></origin><mass value="1"></mass><inertia ixy="0.0" ixx="0.000" ixz="0.0" iyz="0.0" iyy="0.000" izz="0.0"></inertia></inertial></link><link name="bcc4c2ba"><collision><geometry><box size="0.2 0.2 0.2"></box></geometry><origin xyz="0 0.0 0.0" rpy="0 0 0"></origin></collision><visual><geometry><box size="0.2 0.2 0.2"></box></geometry><origin xyz="0 0.0 0" rpy="0 0 0"></origin><material name="white"><color rgba="1 1.0 1.0 1.0"></color></material></visual><inertial><origin xyz="0 0 0" rpy="0 0 0"></origin><mass value="1"></mass><inertia ixy="0.0" ixx="0.000" ixz="0.0" iyz="0.0" iyy="0.000" izz="0.0"></inertia></inertial></link><link name="ac6cf6e8"><collision><geometry><box size="0.2 0.2 0.2"></box></geometry><origin xyz="0 0.0 0.0" rpy="0 0 0"></origin></collision><visual><geometry><box size="0.2 0.2 0.2"></box></geometry><origin xyz="0 0.0 0" rpy="0 0 0"></origin><material name="white"><color rgba="1 1.0 1.0 1.0"></color></material></visual><inertial><origin xyz="0 0 0" rpy="0 0 0"></origin><mass value="1"></mass><inertia ixy="0.0" ixx="0.000" ixz="0.0" iyz="0.0" iyy="0.000" izz="0.0"></inertia></inertial></link><link name="9ec0e600"><collision><geometry><box size="0.2 0.2 0.2"></box></geometry><origin xyz="0 0.0 0.0" rpy="0 0 0"></origin></collision><visual><geometry><box size="0.2 0.2 0.2"></box></geometry><origin xyz="0 0.0 0" rpy="0 0 0"></origin><material name="white"><color rgba="1 1.0 1.0 1.0"></color></material></visual><inertial><origin xyz="0 0 0" rpy="0 0 0"></origin><mass value="1"></mass><inertia ixy="0.0" ixx="0.000" ixz="0.0" iyz="0.0" iyy="0.000" izz="0.0"></inertia></inertial></link><link name="f35b71d8"><collision><geometry><box size="0.2 0.2 0.2"></box></geometry><origin xyz="0 0.0 0.0" rpy="0 0 0"></origin></collision><visual><geometry><box size="0.2 0.2 0.2"></box></geometry><origin xyz="0 0.0 0" rpy="0 0 0"></origin><material name="white"><color rgba="1 1.0 1.0 1.0"></color></material></visual><inertial><origin xyz="0 0 0" rpy="0 0 0"></origin><mass value="1"></mass><inertia ixy="0.0" ixx="0.000" ixz="0.0" iyz="0.0" iyy="0.000" izz="0.0"></inertia></inertial></link><link name="87d6d9a5"><collision><geometry><box size="0.2 0.2 0.2"></box></geometry><origin xyz="0 0.0 0.0" rpy="0 0 0"></origin></collision><visual><geometry><box size="0.2 0.2 0.2"></box></geometry><origin xyz="0 0.0 0" rpy="0 0 0"></origin><material name="white"><color rgba="1 1.0 1.0 1.0"></color></material></visual><inertial><origin xyz="0 0 0" rpy="0 0 0"></origin><mass value="1"></mass><inertia ixy="0.0" ixx="0.000" ixz="0.0" iyz="0.0" iyy="0.000" izz="0.0"></inertia></inertial></link><link name="ff371f0e"><collision><geometry><box size="0.2 0.2 0.2"></box></geometry><origin xyz="0 0.0 0.0" rpy="0 0 0"></origin></collision><visual><geometry><box size="0.2 0.2 0.2"></box></geometry><origin xyz="0 0.0 0" rpy="0 0 0"></origin><material name="white"><color rgba="1 1.0 1.0 1.0"></color></material></visual><inertial><origin xyz="0 0 0" rpy="0 0 0"></origin><mass value="1"></mass><inertia ixy="0.0" ixx="0.000" ixz="0.0" iyz="0.0" iyy="0.000" izz="0.0"></inertia></inertial></link><link name="f49de8b1"><collision><geometry><box size="0.2 0.2 0.2"></box></geometry><origin xyz="0 0.0 0.0" rpy="0 0 0"></origin></collision><visual><geometry><box size="0.2 0.2 0.2"></box></geometry><origin xyz="0 0.0 0" rpy="0 0 0"></origin><material name="white"><color rgba="1 1.0 1.0 1.0"></color></material></visual><inertial><origin xyz="0 0 0" rpy="0 0 0"></origin><mass value="1"></mass><inertia ixy="0.0" ixx="0.000" ixz="0.0" iyz="0.0" iyy="0.000" izz="0.0"></inertia></inertial></link><link name="581c2250"><collision><geometry><box size="0.2 0.2 0.2"></box></geometry><origin xyz="0 0.0 0.0" rpy="0 0 0"></origin></collision><visual><geometry><box size="0.2 0.2 0.2"></box></geometry><origin xyz="0 0.0 0" rpy="0 0 0"></origin><material name="white"><color rgba="1 1.0 1.0 1.0"></color></material></visual><inertial><origin xyz="0 0 0" rpy="0 0 0"></origin><mass value="1"></mass><inertia ixy="0.0" ixx="0.000" ixz="0.0" iyz="0.0" iyy="0.000" izz="0.0"></inertia></inertial></link><link name="31b12c7b"><collision><geometry><box size="0.2 0.2 0.2"></box></geometry><origin xyz="0 0.0 0.0" rpy="0 0 0"></origin></collision><visual><geometry><box size="0.2 0.2 0.2"></box></geometry><origin xyz="0 0.0 0" rpy="0 0 0"></origin><material name="white"><color rgba="1 1.0 1.0 1.0"></color></material></visual><inertial><origin xyz="0 0 0" rpy="0 0 0"></origin><mass value="1"></mass><inertia ixy="0.0" ixx="0.000" ixz="0.0" iyz="0.0" iyy="0.000" izz="0.0"></inertia></inertial></link><link name="24b6d36c"><collision><geometry><box size="0.2 0.2 0.2"></box></geometry><origin xyz="0 0.0 0.0" rpy="0 0 0"></origin></collision><visual><geometry><box size="0.2 0.2 0.2"></box></geometry><origin xyz="0 0.0 0" rpy="0 0 0"></origin><material name="white"><color rgba="1 1.0 1.0 1.0"></color></material></visual><inertial><origin xyz="0 0 0" rpy="0 0 0"></origin><mass value="1"></mass><inertia ixy="0.0" ixx="0.000" ixz="0.0" iyz="0.0" iyy="0.000" izz="0.0"></inertia></inertial></link><link name="7187bc4c"><collision><geometry><box size="0.2 0.2 0.2"></box></geometry><origin xyz="0 0.0 0.0" rpy="0 0 0"></origin></collision><visual><geometry><box size="0.2 0.2 0.2"></box></geometry><origin xyz="0 0.0 0" rpy="0 0 0"></origin><material name="white"><color rgba="1 1.0 1.0 1.0"></color></material></visual><inertial><origin xyz="0 0 0" rpy="0 0 0"></origin><mass value="1"></mass><inertia ixy="0.0" ixx="0.000" ixz="0.0" iyz="0.0" iyy="0.000" izz="0.0"></inertia></inertial></link><link name="181f7e2d"><collision><geometry><box size="0.2 0.2 0.2"></box></geometry><origin xyz="0 0.0 0.0" rpy="0 0 0"></origin></collision><visual><geometry><box size="0.2 0.2 0.2"></box></geometry><origin xyz="0 0.0 0" rpy="0 0 0"></origin><material name="white"><color rgba="1 1.0 1.0 1.0"></color></material></visual><inertial><origin xyz="0 0 0" rpy="0 0 0"></origin><mass value="1"></mass><inertia ixy="0.0" ixx="0.000" ixz="0.0" iyz="0.0" iyy="0.000" izz="0.0"></inertia></inertial></link><link name="f6724a8b"><collision><geometry><box size="0.2 0.2 0.2"></box></geometry><origin xyz="0 0.0 0.0" rpy="0 0 0"></origin></collision><visual><geometry><box size="0.2 0.2 0.2"></box></geometry><origin xyz="0 0.0 0" rpy="0 0 0"></origin><material name="white"><color rgba="1 1.0 1.0 1.0"></color></material></visual><inertial><origin xyz="0 0 0" rpy="0 0 0"></origin><mass value="1"></mass><inertia ixy="0.0" ixx="0.000" ixz="0.0" iyz="0.0" iyy="0.000" izz="0.0"></inertia></inertial></link><link name="a8351408"><collision><geometry><box size="0.2 0.2 0.2"></box></geometry><origin xyz="0 0.0 0.0" rpy="0 0 0"></origin></collision><visual><geometry><box size="0.2 0.2 0.2"></box></geometry><origin xyz="0 0.0 0" rpy="0 0 0"></origin><material name="white"><color rgba="1 1.0 1.0 1.0"></color></material></visual><inertial><origin xyz="0 0 0" rpy="0 0 0"></origin><mass value="1"></mass><inertia ixy="0.0" ixx="0.000" ixz="0.0" iyz="0.0" iyy="0.000" izz="0.0"></inertia></inertial></link><link name="434e5162"><collision><geometry><box size="0.2 0.2 0.2"></box></geometry><origin xyz="0 0.0 0.0" rpy="0 0 0"></origin></collision><visual><geometry><box size="0.2 0.2 0.2"></box></geometry><origin xyz="0 0.0 0" rpy="0 0 0"></origin><material name="white"><color rgba="1 1.0 1.0 1.0"></color></material></visual><inertial><origin xyz="0 0 0" rpy="0 0 0"></origin><mass value="1"></mass><inertia ixy="0.0" ixx="0.000" ixz="0.0" iyz="0.0" iyy="0.000" izz="0.0"></inertia></inertial></link><link name="935073ed"><collision><geometry><box size="0.2 0.2 0.2"></box></geometry><origin xyz="0 0.0 0.0" rpy="0 0 0"></origin></collision><visual><geometry><box size="0.2 0.2 0.2"></box></geometry><origin xyz="0 0.0 0" rpy="0 0 0"></origin><material name="white"><color rgba="1 1.0 1.0 1.0"></color></material></visual><inertial><origin xyz="0 0 0" rpy="0 0 0"></origin><mass value="1"></mass><inertia ixy="0.0" ixx="0.000" ixz="0.0" iyz="0.0" iyy="0.000" izz="0.0"></inertia></inertial></link><link name="d0ee7787"><collision><geometry><box size="0.2 0.2 0.2"></box></geometry><origin xyz="0 0.0 0.0" rpy="0 0 0"></origin></collision><visual><geometry><box size="0.2 0.2 0.2"></box></geometry><origin xyz="0 0.0 0" rpy="0 0 0"></origin><material name="white"><color rgba="1 1.0 1.0 1.0"></color></material></visual><inertial><origin xyz="0 0 0" rpy="0 0 0"></origin><mass value="1"></mass><inertia ixy="0.0" ixx="0.000" ixz="0.0" iyz="0.0" iyy="0.000" izz="0.0"></inertia></inertial></link><link name="1234c791"><collision><geometry><box size="0.2 0.2 0.2"></box></geometry><origin xyz="0 0.0 0.0" rpy="0 0 0"></origin></collision><visual><geometry><box size="0.2 0.2 0.2"></box></geometry><origin xyz="0 0.0 0" rpy="0 0 0"></origin><material name="white"><color rgba="1 1.0 1.0 1.0"></color></material></visual><inertial><origin xyz="0 0 0" rpy="0 0 0"></origin><mass value="1"></mass><inertia ixy="0.0" ixx="0.000" ixz="0.0" iyz="0.0" iyy="0.000" izz="0.0"></inertia></inertial></link><link name="73436589"><collision><geometry><box size="0.2 0.2 0.2"></box></geometry><origin xyz="0 0.0 0.0" rpy="0 0 0"></origin></collision><visual><geometry><box size="0.2 0.2 0.2"></box></geometry><origin xyz="0 0.0 0" rpy="0 0 0"></origin><material name="white"><color rgba="1 1.0 1.0 1.0"></color></material></visual><inertial><origin xyz="0 0 0" rpy="0 0 0"></origin><mass value="1"></mass><inertia ixy="0.0" ixx="0.000" ixz="0.0" iyz="0.0" iyy="0.000" izz="0.0"></inertia></inertial></link><link name="cd08ca72"><collision><geometry><box size="0.2 0.2 0.2"></box></geometry><origin xyz="0 0.0 0.0" rpy="0 0 0"></origin></collision><visual><geometry><box size="0.2 0.2 0.2"></box></geometry><origin xyz="0 0.0 0" rpy="0 0 0"></origin><material name="white"><color rgba="1 1.0 1.0 1.0"></color></material></visual><inertial><origin xyz="0 0 0" rpy="0 0 0"></origin><mass value="1"></mass><inertia ixy="0.0" ixx="0.000" ixz="0.0" iyz="0.0" iyy="0.000" izz="0.0"></inertia></inertial></link><link name="68c0e889"><collision><geometry><box size="0.2 0.2 0.2"></box></geometry><origin xyz="0 0.0 0.0" rpy="0 0 0"></origin></collision><visual><geometry><box size="0.2 0.2 0.2"></box></geometry><origin xyz="0 0.0 0" rpy="0 0 0"></origin><material name="white"><color rgba="1 1.0 1.0 1.0"></color></material></visual><inertial><origin xyz="0 0 0" rpy="0 0 0"></origin><mass value="1"></mass><inertia ixy="0.0" ixx="0.000" ixz="0.0" iyz="0.0" iyy="0.000" izz="0.0"></inertia></inertial></link><link name="c209a4f2"><collision><geometry><box size="0.2 0.2 0.2"></box></geometry><origin xyz="0 0.0 0.0" rpy="0 0 0"></origin></collision><visual><geometry><box size="0.2 0.2 0.2"></box></geometry><origin xyz="0 0.0 0" rpy="0 0 0"></origin><material name="white"><color rgba="1 1.0 1.0 1.0"></color></material></visual><inertial><origin xyz="0 0 0" rpy="0 0 0"></origin><mass value="1"></mass><inertia ixy="0.0" ixx="0.000" ixz="0.0" iyz="0.0" iyy="0.000" izz="0.0"></inertia></inertial></link><link name="a7ead54c"><collision><geometry><box size="0.2 0.2 0.2"></box></geometry><origin xyz="0 0.0 0.0" rpy="0 0 0"></origin></collision><visual><geometry><box size="0.2 0.2 0.2"></box></geometry><origin xyz="0 0.0 0" rpy="0 0 0"></origin><material name="white"><color rgba="1 1.0 1.0 1.0"></color></material></visual><inertial><origin xyz="0 0 0" rpy="0 0 0"></origin><mass value="1"></mass><inertia ixy="0.0" ixx="0.000" ixz="0.0" iyz="0.0" iyy="0.000" izz="0.0"></inertia></inertial></link><link name="3a06f8cc"><collision><geometry><box size="0.2 0.2 0.2"></box></geometry><origin xyz="0 0.0 0.0" rpy="0 0 0"></origin></collision><visual><geometry><box size="0.2 0.2 0.2"></box></geometry><origin xyz="0 0.0 0" rpy="0 0 0"></origin><material name="white"><color rgba="1 1.0 1.0 1.0"></color></material></visual><inertial><origin xyz="0 0 0" rpy="0 0 0"></origin><mass value="1"></mass><inertia ixy="0.0" ixx="0.000" ixz="0.0" iyz="0.0" iyy="0.000" izz="0.0"></inertia></inertial></link><link name="d779f3c3"><collision><geometry><box size="0.2 0.2 0.2"></box></geometry><origin xyz="0 0.0 0.0" rpy="0 0 0"></origin></collision><visual><geometry><box size="0.2 0.2 0.2"></box></geometry><origin xyz="0 0.0 0" rpy="0 0 0"></origin><material name="white"><color rgba="1 1.0 1.0 1.0"></color></material></visual><inertial><origin xyz="0 0 0" rpy="0 0 0"></origin><mass value="1"></mass><inertia ixy="0.0" ixx="0.000" ixz="0.0" iyz="0.0" iyy="0.000" izz="0.0"></inertia></inertial></link><link name="bc24cd03"><collision><geometry><box size="0.2 0.2 0.2"></box></geometry><origin xyz="0 0.0 0.0" rpy="0 0 0"></origin></collision><visual><geometry><box size="0.2 0.2 0.2"></box></geometry><origin xyz="0 0.0 0" rpy="0 0 0"></origin><material name="white"><color rgba="1 1.0 1.0 1.0"></color></material></visual><inertial><origin xyz="0 0 0" rpy="0 0 0"></origin><mass value="1"></mass><inertia ixy="0.0" ixx="0.000" ixz="0.0" iyz="0.0" iyy="0.000" izz="0.0"></inertia></inertial></link><link name="1511502a"><collision><geometry><box size="0.2 0.2 0.2"></box></geometry><origin xyz="0 0.0 0.0" rpy="0 0 0"></origin></collision><visual><geometry><box size="0.2 0.2 0.2"></box></geometry><origin xyz="0 0.0 0" rpy="0 0 0"></origin><material name="white"><color rgba="1 1.0 1.0 1.0"></color></material></visual><inertial><origin xyz="0 0 0" rpy="0 0 0"></origin><mass value="1"></mass><inertia ixy="0.0" ixx="0.000" ixz="0.0" iyz="0.0" iyy="0.000" izz="0.0"></inertia></inertial></link><link name="6722bfd0"><collision><geometry><box size="0.2 0.2 0.2"></box></geometry><origin xyz="0 0.0 0.0" rpy="0 0 0"></origin></collision><visual><geometry><box size="0.2 0.2 0.2"></box></geometry><origin xyz="0 0.0 0" rpy="0 0 0"></origin><material name="white"><color rgba="1 1.0 1.0 1.0"></color></material></visual><inertial><origin xyz="0 0 0" rpy="0 0 0"></origin><mass value="1"></mass><inertia ixy="0.0" ixx="0.000" ixz="0.0" iyz="0.0" iyy="0.000" izz="0.0"></inertia></inertial></link><link name="45cbe0e2"><collision><geometry><box size="0.2 0.2 0.2"></box></geometry><origin xyz="0 0.0 0.0" rpy="0 0 0"></origin></collision><visual><geometry><box size="0.2 0.2 0.2"></box></geometry><origin xyz="0 0.0 0" rpy="0 0 0"></origin><material name="white"><color rgba="1 1.0 1.0 1.0"></color></material></visual><inertial><origin xyz="0 0 0" rpy="0 0 0"></origin><mass value="1"></mass><inertia ixy="0.0" ixx="0.000" ixz="0.0" iyz="0.0" iyy="0.000" izz="0.0"></inertia></inertial></link><link name="2fdbc30e"><collision><geometry><box size="0.2 0.2 0.2"></box></geometry><origin xyz="0 0.0 0.0" rpy="0 0 0"></origin></collision><visual><geometry><box size="0.2 0.2 0.2"></box></geometry><origin xyz="0 0.0 0" rpy="0 0 0"></origin><material name="white"><color rgba="1 1.0 1.0 1.0"></color></material></visual><inertial><origin xyz="0 0 0" rpy="0 0 0"></origin><mass value="1"></mass><inertia ixy="0.0" ixx="0.000" ixz="0.0" iyz="0.0" iyy="0.000" izz="0.0"></inertia></inertial></link><link name="c0a43814"><collision><geometry><box size="0.2 0.2 0.2"></box></geometry><origin xyz="0 0.0 0.0" rpy="0 0 0"></origin></collision><visual><geometry><box size="0.2 0.2 0.2"></box></geometry><origin xyz="0 0.0 0" rpy="0 0 0"></origin><material name="white"><color rgba="1 1.0 1.0 1.0"></color></material></visual><inertial><origin xyz="0 0 0" rpy="0 0 0"></origin><mass value="1"></mass><inertia ixy="0.0" ixx="0.000" ixz="0.0" iyz="0.0" iyy="0.000" izz="0.0"></inertia></inertial></link><link name="d1ea9a80"><collision><geometry><box size="0.2 0.2 0.2"></box></geometry><origin xyz="0 0.0 0.0" rpy="0 0 0"></origin></collision><visual><geometry><box size="0.2 0.2 0.2"></box></geometry><origin xyz="0 0.0 0" rpy="0 0 0"></origin><material name="white"><color rgba="1 1.0 1.0 1.0"></color></material></visual><inertial><origin xyz="0 0 0" rpy="0 0 0"></origin><mass value="1"></mass><inertia ixy="0.0" ixx="0.000" ixz="0.0" iyz="0.0" iyy="0.000" izz="0.0"></inertia></inertial></link><link name="63bd3236"><collision><geometry><box size="0.2 0.2 0.2"></box></geometry><origin xyz="0 0.0 0.0" rpy="0 0 0"></origin></collision><visual><geometry><box size="0.2 0.2 0.2"></box></geometry><origin xyz="0 0.0 0" rpy="0 0 0"></origin><material name="white"><color rgba="1 1.0 1.0 1.0"></color></material></visual><inertial><origin xyz="0 0 0" rpy="0 0 0"></origin><mass value="1"></mass><inertia ixy="0.0" ixx="0.000" ixz="0.0" iyz="0.0" iyy="0.000" izz="0.0"></inertia></inertial></link><link name="84c3bc2a"><collision><geometry><box size="0.2 0.2 0.2"></box></geometry><origin xyz="0 0.0 0.0" rpy="0 0 0"></origin></collision><visual><geometry><box size="0.2 0.2 0.2"></box></geometry><origin xyz="0 0.0 0" rpy="0 0 0"></origin><material name="white"><color rgba="1 1.0 1.0 1.0"></color></material></visual><inertial><origin xyz="0 0 0" rpy="0 0 0"></origin><mass value="1"></mass><inertia ixy="0.0" ixx="0.000" ixz="0.0" iyz="0.0" iyy="0.000" izz="0.0"></inertia></inertial></link><link name="0231e818"><collision><geometry><box size="0.2 0.2 0.2"></box></geometry><origin xyz="0 0.0 0.0" rpy="0 0 0"></origin></collision><visual><geometry><box size="0.2 0.2 0.2"></box></geometry><origin xyz="0 0.0 0" rpy="0 0 0"></origin><material name="white"><color rgba="1 1.0 1.0 1.0"></color></material></visual><inertial><origin xyz="0 0 0" rpy="0 0 0"></origin><mass value="1"></mass><inertia ixy="0.0" ixx="0.000" ixz="0.0" iyz="0.0" iyy="0.000" izz="0.0"></inertia></inertial></link><link name="9c2da2f4"><collision><geometry><box size="0.2 0.2 0.2"></box></geometry><origin xyz="0 0.0 0.0" rpy="0 0 0"></origin></collision><visual><geometry><box size="0.2 0.2 0.2"></box></geometry><origin xyz="0 0.0 0" rpy="0 0 0"></origin><material name="white"><color rgba="1 1.0 1.0 1.0"></color></material></visual><inertial><origin xyz="0 0 0" rpy="0 0 0"></origin><mass value="1"></mass><inertia ixy="0.0" ixx="0.000" ixz="0.0" iyz="0.0" iyy="0.000" izz="0.0"></inertia></inertial></link><link name="0dc9647a"><collision><geometry><box size="0.2 0.2 0.2"></box></geometry><origin xyz="0 0.0 0.0" rpy="0 0 0"></origin></collision><visual><geometry><box size="0.2 0.2 0.2"></box></geometry><origin xyz="0 0.0 0" rpy="0 0 0"></origin><material name="white"><color rgba="1 1.0 1.0 1.0"></color></material></visual><inertial><origin xyz="0 0 0" rpy="0 0 0"></origin><mass value="1"></mass><inertia ixy="0.0" ixx="0.000" ixz="0.0" iyz="0.0" iyy="0.000" izz="0.0"></inertia></inertial></link><link name="5392b5b2"><collision><geometry><box size="0.2 0.2 0.2"></box></geometry><origin xyz="0 0.0 0.0" rpy="0 0 0"></origin></collision><visual><geometry><box size="0.2 0.2 0.2"></box></geometry><origin xyz="0 0.0 0" rpy="0 0 0"></origin><material name="white"><color rgba="1 1.0 1.0 1.0"></color></material></visual><inertial><origin xyz="0 0 0" rpy="0 0 0"></origin><mass value="1"></mass><inertia ixy="0.0" ixx="0.000" ixz="0.0" iyz="0.0" iyy="0.000" izz="0.0"></inertia></inertial></link><link name="d7336e02"><collision><geometry><box size="0.2 0.2 0.2"></box></geometry><origin xyz="0 0.0 0.0" rpy="0 0 0"></origin></collision><visual><geometry><box size="0.2 0.2 0.2"></box></geometry><origin xyz="0 0.0 0" rpy="0 0 0"></origin><material name="white"><color rgba="1 1.0 1.0 1.0"></color></material></visual><inertial><origin xyz="0 0 0" rpy="0 0 0"></origin><mass value="1"></mass><inertia ixy="0.0" ixx="0.000" ixz="0.0" iyz="0.0" iyy="0.000" izz="0.0"></inertia></inertial></link><link name="43be07d9"><collision><geometry><box size="0.2 0.2 0.2"></box></geometry><origin xyz="0 0.0 0.0" rpy="0 0 0"></origin></collision><visual><geometry><box size="0.2 0.2 0.2"></box></geometry><origin xyz="0 0.0 0" rpy="0 0 0"></origin><material name="white"><color rgba="1 1.0 1.0 1.0"></color></material></visual><inertial><origin xyz="0 0 0" rpy="0 0 0"></origin><mass value="1"></mass><inertia ixy="0.0" ixx="0.000" ixz="0.0" iyz="0.0" iyy="0.000" izz="0.0"></inertia></inertial></link><link name="b3ea44e5"><collision><geometry><box size="0.2 0.2 0.2"></box></geometry><origin xyz="0 0.0 0.0" rpy="0 0 0"></origin></collision><visual><geometry><box size="0.2 0.2 0.2"></box></geometry><origin xyz="0 0.0 0" rpy="0 0 0"></origin><material name="white"><color rgba="1 1.0 1.0 1.0"></color></material></visual><inertial><origin xyz="0 0 0" rpy="0 0 0"></origin><mass value="1"></mass><inertia ixy="0.0" ixx="0.000" ixz="0.0" iyz="0.0" iyy="0.000" izz="0.0"></inertia></inertial></link><link name="adb2dd0f"><collision><geometry><box size="0.2 0.2 0.2"></box></geometry><origin xyz="0 0.0 0.0" rpy="0 0 0"></origin></collision><visual><geometry><box size="0.2 0.2 0.2"></box></geometry><origin xyz="0 0.0 0" rpy="0 0 0"></origin><material name="white"><color rgba="1 1.0 1.0 1.0"></color></material></visual><inertial><origin xyz="0 0 0" rpy="0 0 0"></origin><mass value="1"></mass><inertia ixy="0.0" ixx="0.000" ixz="0.0" iyz="0.0" iyy="0.000" izz="0.0"></inertia></inertial></link><link name="f8367eb9"><collision><geometry><box size="0.2 0.2 0.2"></box></geometry><origin xyz="0 0.0 0.0" rpy="0 0 0"></origin></collision><visual><geometry><box size="0.2 0.2 0.2"></box></geometry><origin xyz="0 0.0 0" rpy="0 0 0"></origin><material name="white"><color rgba="1 1.0 1.0 1.0"></color></material></visual><inertial><origin xyz="0 0 0" rpy="0 0 0"></origin><mass value="1"></mass><inertia ixy="0.0" ixx="0.000" ixz="0.0" iyz="0.0" iyy="0.000" izz="0.0"></inertia></inertial></link><link name="ad8c639e"><collision><geometry><box size="0.2 0.2 0.2"></box></geometry><origin xyz="0 0.0 0.0" rpy="0 0 0"></origin></collision><visual><geometry><box size="0.2 0.2 0.2"></box></geometry><origin xyz="0 0.0 0" rpy="0 0 0"></origin><material name="white"><color rgba="1 1.0 1.0 1.0"></color></material></visual><inertial><origin xyz="0 0 0" rpy="0 0 0"></origin><mass value="1"></mass><inertia ixy="0.0" ixx="0.000" ixz="0.0" iyz="0.0" iyy="0.000" izz="0.0"></inertia></inertial></link><link name="23d9b26f"><collision><geometry><box size="0.2 0.2 0.2"></box></geometry><origin xyz="0 0.0 0.0" rpy="0 0 0"></origin></collision><visual><geometry><box size="0.2 0.2 0.2"></box></geometry><origin xyz="0 0.0 0" rpy="0 0 0"></origin><material name="white"><color rgba="1 1.0 1.0 1.0"></color></material></visual><inertial><origin xyz="0 0 0" rpy="0 0 0"></origin><mass value="1"></mass><inertia ixy="0.0" ixx="0.000" ixz="0.0" iyz="0.0" iyy="0.000" izz="0.0"></inertia></inertial></link><link name="31c6b757"><collision><geometry><box size="0.2 0.2 0.2"></box></geometry><origin xyz="0 0.0 0.0" rpy="0 0 0"></origin></collision><visual><geometry><box size="0.2 0.2 0.2"></box></geometry><origin xyz="0 0.0 0" rpy="0 0 0"></origin><material name="white"><color rgba="1 1.0 1.0 1.0"></color></material></visual><inertial><origin xyz="0 0 0" rpy="0 0 0"></origin><mass value="1"></mass><inertia ixy="0.0" ixx="0.000" ixz="0.0" iyz="0.0" iyy="0.000" izz="0.0"></inertia></inertial></link><link name="dc94f799"><collision><geometry><box size="0.2 0.2 0.2"></box></geometry><origin xyz="0 0.0 0.0" rpy="0 0 0"></origin></collision><visual><geometry><box size="0.2 0.2 0.2"></box></geometry><origin xyz="0 0.0 0" rpy="0 0 0"></origin><material name="white"><color rgba="1 1.0 1.0 1.0"></color></material></visual><inertial><origin xyz="0 0 0" rpy="0 0 0"></origin><mass value="1"></mass><inertia ixy="0.0" ixx="0.000" ixz="0.0" iyz="0.0" iyy="0.000" izz="0.0"></inertia></inertial></link><link name="b7a98a4a"><collision><geometry><box size="0.2 0.2 0.2"></box></geometry><origin xyz="0 0.0 0.0" rpy="0 0 0"></origin></collision><visual><geometry><box size="0.2 0.2 0.2"></box></geometry><origin xyz="0 0.0 0" rpy="0 0 0"></origin><material name="white"><color rgba="1 1.0 1.0 1.0"></color></material></visual><inertial><origin xyz="0 0 0" rpy="0 0 0"></origin><mass value="1"></mass><inertia ixy="0.0" ixx="0.000" ixz="0.0" iyz="0.0" iyy="0.000" izz="0.0"></inertia></inertial></link><link name="662e1da3"><collision><geometry><box size="0.2 0.2 0.2"></box></geometry><origin xyz="0 0.0 0.0" rpy="0 0 0"></origin></collision><visual><geometry><box size="0.2 0.2 0.2"></box></geometry><origin xyz="0 0.0 0" rpy="0 0 0"></origin><material name="white"><color rgba="1 1.0 1.0 1.0"></color></material></visual><inertial><origin xyz="0 0 0" rpy="0 0 0"></origin><mass value="1"></mass><inertia ixy="0.0" ixx="0.000" ixz="0.0" iyz="0.0" iyy="0.000" izz="0.0"></inertia></inertial></link><link name="e400f108"><collision><geometry><box size="0.2 0.2 0.2"></box></geometry><origin xyz="0 0.0 0.0" rpy="0 0 0"></origin></collision><visual><geometry><box size="0.2 0.2 0.2"></box></geometry><origin xyz="0 0.0 0" rpy="0 0 0"></origin><material name="white"><color rgba="1 1.0 1.0 1.0"></color></material></visual><inertial><origin xyz="0 0 0" rpy="0 0 0"></origin><mass value="1"></mass><inertia ixy="0.0" ixx="0.000" ixz="0.0" iyz="0.0" iyy="0.000" izz="0.0"></inertia></inertial></link><joint name="f35b71d8bcc4c2ba" type="revolute"><origin xyz="0 0.2 0" rpy="0 0 0"></origin><parent link="f35b71d8"></parent><child link="bcc4c2ba"></child><limit velocity="0" lower="-1.9" upper="1.9" effort="0"></limit><type>revolute</type><axis xyz="0 0 1"></axis></joint><joint name="f35b71d8ac6cf6e8" type="revolute"><origin xyz="0 -0.2 0" rpy="0 0 0"></origin><parent link="f35b71d8"></parent><child link="ac6cf6e8"></child><limit velocity="0" lower="-1.9" upper="1.9" effort="0"></limit><type>revolute</type><axis xyz="0 0 1"></axis></joint><joint name="f35b71d89ec0e600" type="revolute"><origin xyz="0.2 0 0" rpy="0 0 0"></origin><parent link="f35b71d8"></parent><child link="9ec0e600"></child><limit velocity="0" lower="-1.9" upper="1.9" effort="0"></limit><type>revolute</type><axis xyz="0 0 1"></axis></joint><joint name="9ec0e60062d6a4e2" type="revolute"><origin xyz="0 0.2 0" rpy="0 0 0"></origin><parent link="9ec0e600"></parent><child link="62d6a4e2"></child><limit velocity="0" lower="-1.9" upper="1.9" effort="0"></limit><type>revolute</type><axis xyz="0 0 1"></axis></joint><joint name="62d6a4e2b066414d" type="revolute"><origin xyz="0 0.2 0" rpy="0 0 0"></origin><parent link="62d6a4e2"></parent><child link="b066414d"></child><limit velocity="0" lower="-1.9" upper="1.9" effort="0"></limit><type>revolute</type><axis xyz="0 0 1"></axis></joint><joint name="62d6a4e238092bac" type="revolute"><origin xyz="0 0.2 0" rpy="0 0 0"></origin><parent link="62d6a4e2"></parent><child link="38092bac"></child><limit velocity="0" lower="-1.9" upper="1.9" effort="0"></limit><type>revolute</type><axis xyz="0 0 1"></axis></joint><joint name="38092bac0fd258d7" type="revolute"><origin xyz="0 0.2 0" rpy="0 0 0"></origin><parent link="38092bac"></parent><child link="0fd258d7"></child><limit velocity="0" lower="-1.9" upper="1.9" effort="0"></limit><type>revolute</type><axis xyz="0 0 1"></axis></joint><joint name="181f7e2d7187bc4c" type="revolute"><origin xyz="0.2 0 0" rpy="0 0 0"></origin><parent link="181f7e2d"></parent><child link="7187bc4c"></child><limit velocity="0" lower="-1.9" upper="1.9" effort="0"></limit><type>revolute</type><axis xyz="0 0 1"></axis></joint><joint name="7187bc4c24b6d36c" type="revolute"><origin xyz="0 0.2 0" rpy="0 0 0"></origin><parent link="7187bc4c"></parent><child link="24b6d36c"></child><limit velocity="0" lower="-1.9" upper="1.9" effort="0"></limit><type>revolute</type><axis xyz="0 0 1"></axis></joint><joint name="24b6d36c31b12c7b" type="revolute"><origin xyz="0 0.2 0" rpy="0 0 0"></origin><parent link="24b6d36c"></parent><child link="31b12c7b"></child><limit velocity="0" lower="-1.9" upper="1.9" effort="0"></limit><type>revolute</type><axis xyz="0 0 1"></axis></joint><joint name="31b12c7b581c2250" type="revolute"><origin xyz="0.2 0 0" rpy="0 0 0"></origin><parent link="31b12c7b"></parent><child link="581c2250"></child><limit velocity="0" lower="-1.9" upper="1.9" effort="0"></limit><type>revolute</type><axis xyz="0 0 1"></axis></joint><joint name="581c2250f49de8b1" type="revolute"><origin xyz="0 0.2 0" rpy="0 0 0"></origin><parent link="581c2250"></parent><child link="f49de8b1"></child><limit velocity="0" lower="-1.9" upper="1.9" effort="0"></limit><type>revolute</type><axis xyz="0 0 1"></axis></joint><joint name="f49de8b1ff371f0e" type="revolute"><origin xyz="0 0.2 0" rpy="0 0 0"></origin><parent link="f49de8b1"></parent><child link="ff371f0e"></child><limit velocity="0" lower="-1.9" upper="1.9" effort="0"></limit><type>revolute</type><axis xyz="0 0 1"></axis></joint><joint name="ff371f0e87d6d9a5" type="revolute"><origin xyz="0 0.2 0" rpy="0 0 0"></origin><parent link="ff371f0e"></parent><child link="87d6d9a5"></child><limit velocity="0" lower="-1.9" upper="1.9" effort="0"></limit><type>revolute</type><axis xyz="0 0 1"></axis></joint><joint name="cd08ca7273436589" type="revolute"><origin xyz="0 0.2 0" rpy="0 0 0"></origin><parent link="cd08ca72"></parent><child link="73436589"></child><limit velocity="0" lower="-1.9" upper="1.9" effort="0"></limit><type>revolute</type><axis xyz="0 0 1"></axis></joint><joint name="73436589935073ed" type="revolute"><origin xyz="0 0.2 0" rpy="0 0 0"></origin><parent link="73436589"></parent><child link="935073ed"></child><limit velocity="0" lower="-1.9" upper="1.9" effort="0"></limit><type>revolute</type><axis xyz="0 0 1"></axis></joint><joint name="73436589d0ee7787" type="revolute"><origin xyz="0.2 0 0" rpy="0 0 0"></origin><parent link="73436589"></parent><child link="d0ee7787"></child><limit velocity="0" lower="-1.9" upper="1.9" effort="0"></limit><type>revolute</type><axis xyz="0 0 1"></axis></joint><joint name="734365891234c791" type="revolute"><origin xyz="0.2 0 0" rpy="0 0 0"></origin><parent link="73436589"></parent><child link="1234c791"></child><limit velocity="0" lower="-1.9" upper="1.9" effort="0"></limit><type>revolute</type><axis xyz="0 0 1"></axis></joint><joint name="1234c791434e5162" type="revolute"><origin xyz="0 0.2 0" rpy="0 0 0"></origin><parent link="1234c791"></parent><child link="434e5162"></child><limit velocity="0" lower="-1.9" upper="1.9" effort="0"></limit><type>revolute</type><axis xyz="0 0 1"></axis></joint><joint name="434e5162a8351408" type="revolute"><origin xyz="0 0.2 0" rpy="0 0 0"></origin><parent link="434e5162"></parent><child link="a8351408"></child><limit velocity="0" lower="-1.9" upper="1.9" effort="0"></limit><type>revolute</type><axis xyz="0 0 1"></axis></joint><joint name="a8351408f6724a8b" type="revolute"><origin xyz="0 0.2 0" rpy="0 0 0"></origin><parent link="a8351408"></parent><child link="f6724a8b"></child><limit velocity="0" lower="-1.9" upper="1.9" effort="0"></limit><type>revolute</type><axis xyz="0 0 1"></axis></joint><joint name="a7ead54cc209a4f2" type="revolute"><origin xyz="0 0.2 0" rpy="0 0 0"></origin><parent link="a7ead54c"></parent><child link="c209a4f2"></child><limit velocity="0" lower="-1.9" upper="1.9" effort="0"></limit><type>revolute</type><axis xyz="0 0 1"></axis></joint><joint name="c209a4f268c0e889" type="revolute"><origin xyz="0.2 0 0" rpy="0 0 0"></origin><parent link="c209a4f2"></parent><child link="68c0e889"></child><limit velocity="0" lower="-1.9" upper="1.9" effort="0"></limit><type>revolute</type><axis xyz="0 0 1"></axis></joint><joint name="bc24cd03d779f3c3" type="revolute"><origin xyz="0 0.2 0" rpy="0 0 0"></origin><parent link="bc24cd03"></parent><child link="d779f3c3"></child><limit velocity="0" lower="-1.9" upper="1.9" effort="0"></limit><type>revolute</type><axis xyz="0 0 1"></axis></joint><joint name="d779f3c33a06f8cc" type="revolute"><origin xyz="0 0.2 0" rpy="0 0 0"></origin><parent link="d779f3c3"></parent><child link="3a06f8cc"></child><limit velocity="0" lower="-1.9" upper="1.9" effort="0"></limit><type>revolute</type><axis xyz="0 0 1"></axis></joint><joint name="2fdbc30e45cbe0e2" type="revolute"><origin xyz="0 0.2 0" rpy="0 0 0"></origin><parent link="2fdbc30e"></parent><child link="45cbe0e2"></child><limit velocity="0" lower="-1.9" upper="1.9" effort="0"></limit><type>revolute</type><axis xyz="0 0 1"></axis></joint><joint name="45cbe0e26722bfd0" type="revolute"><origin xyz="0 0.2 0" rpy="0 0 0"></origin><parent link="45cbe0e2"></parent><child link="6722bfd0"></child><limit velocity="0" lower="-1.9" upper="1.9" effort="0"></limit><type>revolute</type><axis xyz="0 0 1"></axis></joint><joint name="84c3bc2a63bd3236" type="revolute"><origin xyz="0 0.2 0" rpy="0 0 0"></origin><parent link="84c3bc2a"></parent><child link="63bd3236"></child><limit velocity="0" lower="-1.9" upper="1.9" effort="0"></limit><type>revolute</type><axis xyz="0 0 1"></axis></joint><joint name="63bd3236d1ea9a80" type="revolute"><origin xyz="0 0.2 0" rpy="0 0 0"></origin><parent link="63bd3236"></parent><child link="d1ea9a80"></child><limit velocity="0" lower="-1.9" upper="1.9" effort="0"></limit><type>revolute</type><axis xyz="0 0 1"></axis></joint><joint name="d1ea9a80c0a43814" type="revolute"><origin xyz="0 0.2 0" rpy="0 0 0"></origin><parent link="d1ea9a80"></parent><child link="c0a43814"></child><limit velocity="0" lower="-1.9" upper="1.9" effort="0"></limit><type>revolute</type><axis xyz="0 0 1"></axis></joint><joint name="d7336e025392b5b2" type="revolute"><origin xyz="0 0.2 0" rpy="0 0 0"></origin><parent link="d7336e02"></parent><child link="5392b5b2"></child><limit velocity="0" lower="-1.9" upper="1.9" effort="0"></limit><type>revolute</type><axis xyz="0 0 1"></axis></joint><joint name="5392b5b29c2da2f4" type="revolute"><origin xyz="0 0.2 0" rpy="0 0 0"></origin><parent link="5392b5b2"></parent><child link="9c2da2f4"></child><limit velocity="0" lower="-1.9" upper="1.9" effort="0"></limit><type>revolute</type><axis xyz="0 0 1"></axis></joint><joint name="5392b5b20dc9647a" type="revolute"><origin xyz="0.2 0 0" rpy="0 0 0"></origin><parent link="5392b5b2"></parent><child link="0dc9647a"></child><limit velocity="0" lower="-1.9" upper="1.9" effort="0"></limit><type>revolute</type><axis xyz="0 0 1"></axis></joint><joint name="0dc9647a0231e818" type="revolute"><origin xyz="0 0.2 0" rpy="0 0 0"></origin><parent link="0dc9647a"></parent><child link="0231e818"></child><limit velocity="0" lower="-1.9" upper="1.9" effort="0"></limit><type>revolute</type><axis xyz="0 0 1"></axis></joint><joint name="e400f108662e1da3" type="revolute"><origin xyz="0 0.2 0" rpy="0 0 0"></origin><parent link="e400f108"></parent><child link="662e1da3"></child><limit velocity="0" lower="-1.9" upper="1.9" effort="0"></limit><type>revolute</type><axis xyz="0 0 1"></axis></joint><joint name="662e1da3b7a98a4a" type="revolute"><origin xyz="0 0.2 0" rpy="0 0 0"></origin><parent link="662e1da3"></parent><child link="b7a98a4a"></child><limit velocity="0" lower="-1.9" upper="1.9" effort="0"></limit><type>revolute</type><axis xyz="0 0 1"></axis></joint><joint name="b7a98a4adc94f799" type="revolute"><origin xyz="0 0.2 0" rpy="0 0 0"></origin><parent link="b7a98a4a"></parent><child link="dc94f799"></child><limit velocity="0" lower="-1.9" upper="1.9" effort="0"></limit><type>revolute</type><axis xyz="0 0 1"></axis></joint><joint name="dc94f79931c6b757" type="revolute"><origin xyz="0 0.2 0" rpy="0 0 0"></origin><parent link="dc94f799"></parent><child link="31c6b757"></child><limit velocity="0" lower="-1.9" upper="1.9" effort="0"></limit><type>revolute</type><axis xyz="0 0 1"></axis></joint><joint name="31c6b757ad8c639e" type="revolute"><origin xyz="0 0.2 0" rpy="0 0 0"></origin><parent link="31c6b757"></parent><child link="ad8c639e"></child><limit velocity="0" lower="-1.9" upper="1.9" effort="0"></limit><type>revolute</type><axis xyz="0 0 1"></axis></joint><joint name="31c6b75723d9b26f" type="revolute"><origin xyz="0 0.2 0" rpy="0 0 0"></origin><parent link="31c6b757"></parent><child link="23d9b26f"></child><limit velocity="0" lower="-1.9" upper="1.9" effort="0"></limit><type>revolute</type><axis xyz="0 0 1"></axis></joint><joint name="23d9b26ff8367eb9" type="revolute"><origin xyz="0 0.2 0" rpy="0 0 0"></origin><parent link="23d9b26f"></parent><child link="f8367eb9"></child><limit velocity="0" lower="-1.9" upper="1.9" effort="0"></limit><type>revolute</type><axis xyz="0 0 1"></axis></joint><joint name="f8367eb9adb2dd0f" type="revolute"><origin xyz="0 0.2 0" rpy="0 0 0"></origin><parent link="f8367eb9"></parent><child link="adb2dd0f"></child><limit velocity="0" lower="-1.9" upper="1.9" effort="0"></limit><type>revolute</type><axis xyz="0 0 1"></axis></joint><joint name="adb2dd0fb3ea44e5" type="revolute"><origin xyz="0 0.2 0" rpy="0 0 0"></origin><parent link="adb2dd0f"></parent><child link="b3ea44e5"></child><limit velocity="0" lower="-1.9" upper="1.9" effort="0"></limit><type>revolute</type><axis xyz="0 0 1"></axis></joint><joint name="b3ea44e543be07d9" type="revolute"><origin xyz="0 0.2 0" rpy="0 0 0"></origin><parent link="b3ea44e5"></parent><child link="43be07d9"></child><limit velocity="0" lower="-1.9" upper="1.9" effort="0"></limit><type>revolute</type><axis xyz="0 0 1"></axis></joint></robot>