<?xml version="1.0" encoding="utf-8"?>
<robot name="paul">
	<link name="15183ac2">
		<collision>
			<geometry>
				<box size="0.0114284594376 0.0193991582252 0.099780906054"></box>
			</geometry>
			<origin xyz="0.0 0.0 0.049890453027" rpy="0 0 0"></origin>
		</collision>
		<visual>
			<geometry>
				<box size="0.0114284594376 0.0193991582252 0.099780906054"></box>
			</geometry>
			<origin xyz="0.0 0.0 0.049890453027" rpy="0 0 0"></origin>
			<material name="white">
				<color rgba="1.0 1.0 1.0 1.0"></color>
			</material>
		</visual>
		<inertial>
			<origin xyz="0.0 0.0 0.049890453027" rpy="0 0 0"></origin>
			<mass value="0.002765209452"></mass>
			<inertia ixy="0.0" ixx="0.000" ixz="0.0" iyz="0.0" iyy="0.000" izz="0.0"></inertia>
		</inertial>
	</link>
	<link name="56c25184">
		<collision>
			<geometry>
				<box size="0.164163330301 0.0557477243164 14.6916956498"></box>
			</geometry>
			<origin xyz="0.0 0.0 7.3458478249" rpy="0 0 0"></origin>
		</collision>
		<visual>
			<geometry>
				<box size="0.164163330301 0.0557477243164 14.6916956498"></box>
			</geometry>
			<origin xyz="0.0 0.0 7.3458478249" rpy="0 0 0"></origin>
			<material name="white">
				<color rgba="1.0 1.0 1.0 1.0"></color>
			</material>
		</visual>
		<inertial>
			<origin xyz="0.0 0.0 7.3458478249" rpy="0 0 0"></origin>
			<mass value="16.8068077994"></mass>
			<inertia ixy="0.0" ixx="0.000" ixz="0.0" iyz="0.0" iyy="0.000" izz="0.0"></inertia>
		</inertial>
	</link>
	<link name="29907e43">
		<collision>
			<geometry>
				<box size="0.0145291784676 0.0120034111686 0.0628115599706"></box>
			</geometry>
			<origin xyz="0 0.0 0.0" rpy="0 0 0"></origin>
		</collision>
		<visual>
			<geometry>
				<box size="0.0145291784676 0.0120034111686 0.0628115599706"></box>
			</geometry>
			<origin xyz="0 0.0 0" rpy="0 0 0"></origin>
			<material name="white">
				<color rgba="1.0 1.0 1.0 1.0"></color>
			</material>
		</visual>
		<inertial>
			<origin xyz="0 0 0" rpy="0 0 0"></origin>
			<mass value="0.00136928967617"></mass>
			<inertia ixy="0.0" ixx="0.000" ixz="0.0" iyz="0.0" iyy="0.000" izz="0.0"></inertia>
		</inertial>
	</link>
	<joint name="29907e4356c25184" type="revolute">
		<origin xyz="0.0 0.0 -14.6916956498" rpy="0 0 0"></origin>
		<parent link="29907e43"></parent>
		<limit velocity="0.275109006267" lower="-1.9" upper="0.414710442446" effort="0.420992724841"></limit>
		<child link="56c25184"></child>
		<phase>0</phase>
		<type>revolute</type>
		<axis xyz="0 0 1"></axis>
	</joint>
	<joint name="56c2518415183ac2" type="revolute">
		<origin xyz="0.0 0.0 -0.099780906054" rpy="0 0 0"></origin>
		<parent link="56c25184"></parent>
		<limit velocity="0" lower="-1.9" upper="1.9" effort="0"></limit>
		<child link="15183ac2"></child>
		<phase>0</phase>
		<type>revolute</type>
		<axis xyz="1 0 0"></axis>
	</joint>
</robot>